Workbook
Name Allkortsfaktura_629_011_192_December_2013: Kontoutdrag_officiella!$A$456:$E$472

Sheet Kontoutdrag_officiella
A1: y | B1: m | C1: d | D1: n | E1: t | F1: g | G1: s | H1: b | L1: c
A2: 2015 | B2: 12 | C2: 30 | D2: PILEGÅRDEN 2 & | E2: -7824 | F2: 0 | G2: =E2 -> -7824 | H2: hyra (inkl. 1k amortering) | L2: Regular
A3: 2015 | B3: 12 | C3: 30 | D3: Periodens köp | E3: -11093.58 | F3: 0 | G3: =E3 -> -11093.58 | H3: spara almänt | L3: Regular
A4: 2015 | B4: 12 | C4: 30 | D4: HSB GÖTEBORG | E4: -4007 | F4: 0 | G4: =E4 -> -4007 | H4: hyra (inkl. 1k amortering) | L4: Regular
A5: 2015 | B5: 12 | C5: 30 | D5: HSB BOKVAR | E5: -207.8 | F5: 0 | G5: =E5 -> -207.8 | H5: hyra (inkl. 1k amortering) | L5: Regular
A6: 2015 | B6: 12 | C6: 30 | D6: FOLKSAM | E6: -153 | F6: 0 | G6: =E6 -> -153 | H6: hemförsäkring | L6: Regular
A7: 2015 | B7: 12 | C7: 30 | D7: 47516877 | E7: 1000 | F7: 0 | G7: =E7 -> 1000 | H7: spara till amortering | L7: Regular
A8: 2015 | B8: 12 | C8: 29 | D8: SV INGENJ | E8: -320 | F8: 0 | G8: =E8 -> -320 | H8: si och akassa | L8: Regular
A9: 2015 | B9: 12 | C9: 29 | D9: COM HEM AB | E9: -299 | F9: 0 | G9: =E9 -> -299 | H9: internet | L9: Regular
A10: 2015 | B10: 12 | C10: 29 | D10: AKADEMIKERFÖ | E10: -298 | F10: 0 | G10: =E10 -> -298 | H10: liv- o sjukförsäkring etc | L10: Regular
A11: 2015 | B11: 12 | C11: 28 | D11: UNICEF | E11: -100 | F11: 0 | G11: =E11 -> -100 | H11: röda korset | L11: Regular
A12: 2015 | B12: 12 | C12: 28 | D12: Månadsbuffert | E12: -5000 | F12: 0 | G12: =E12 -> -5000 | H12: - | L12: Regular
A13: 2015 | B13: 12 | C13: 28 | D13: Månadsbuffert | E13: 5000 | F13: 0 | G13: =E13 -> 5000 | H13: - | L13: Regular
A14: 2015 | B14: 12 | C14: 28 | D14: LUX RÄNTA | E14: -1250 | F14: 0 | G14: =E14 -> -1250 | H14: spara till amortering | L14: Regular
A15: 2015 | B15: 12 | C15: 27 | D15: QSTAR SIML$NGSDALEN | E15: -402.65 | F15: 0 | G15: =E15 -> -402.65 | H15: spara till russel övrigt | L15: Regular
A16: 2015 | B16: 12 | C16: 25 | D16: SVENSSON,KAROL | E16: 60 | F16: 0 | G16: =E16 -> 60 | H16: spara till russel övrigt | L16: Regular
A17: 2015 | B17: 12 | C17: 25 | D17: CITY GROSS VARNAMO | E17: -278.4 | F17: 0 | G17: =E17 -> -278.4 | H17: spara till russel övrigt | L17: Regular
A18: 2015 | B18: 12 | C18: 25 | D18: CITY GROSS VARNAMO | E18: -113 | F18: 0 | G18: =E18 -> -113 | H18: spara till russel övrigt | L18: Regular
A19: 2015 | B19: 12 | C19: 24 | D19: GODJUL MOP | E19: 1000 | F19: 0 | G19: =E19 -> 1000 | H19: presenter | L19: Regular
... A64: 2015 | B64: 11 | C64: 30 | D64: CENTRALA STUDI | E64: -3061 | F64: 0 | G64: =E64 -> -3061 | H64: csn | L64: Regular
A65: 2015 | B65: 11 | C65: 30 | D65: 47516877 | E65: 1000 | F65: 0 | G65: =E65 -> 1000 | H65: spara till amortering | L65: Regular
A66: 2015 | B66: 11 | C66: 28 | D66: PRESSBYR$N 4250148 G@TEBORG | E66: -110 | F66: 0 | G66: =E66 -> -110 | H66: alkohol | L66: Regular
A67: 2015 | B67: 11 | C67: 28 | D67: Marcus Bjerkst | E67: -111 | F67: 0 | G67: =E67 -> -111 | H67: spara till russel övrigt | L67: Regular
A68: 2015 | B68: 11 | C68: 28 | D68: M}ngatan AB G¦teborg | E68: -129 | F68: 0 | G68: =E68 -> -129 | H68: nöjes utemat | L68: Regular
A69: 2015 | B69: 11 | C69: 28 | D69: JOHAN GRADEEN | E69: 79 | F69: 0 | G69: =E69 -> 79 | H69: spara till russel övrigt | L69: Regular
A70: 2015 | B70: 11 | C70: 27 | D70: SV INGENJ | E70: -320 | F70: 0 | G70: =E70 -> -320 | H70: si och akassa | L70: Regular
A71: 2015 | B71: 11 | C71: 27 | D71: COM HEM AB | E71: -299 | F71: 0 | G71: =E71 -> -299 | H71: internet | L71: Regular
A72: 2015 | B72: 11 | C72: 27 | D72: AKADEMIKERFÖ | E72: -303 | F72: 0 | G72: =E72 -> -303 | H72: liv- o sjukförsäkring etc | L72: Regular
A73: 2015 | B73: 11 | C73: 26 | D73: OL REPUBLIKEN GOTEBORG | E73: -141 | F73: 0 | G73: =E73 -> -141 | H73: mat i samband med supa | L73: Regular
A74: 2015 | B74: 11 | C74: 26 | D74: LUX RÄNTA | E74: -1250 | F74: 0 | G74: =E74 -> -1250 | H74: spara till amortering | L74: Regular
A75: 2015 | B75: 11 | C75: 26 | D75: JAFARIS DONUTS G@TEBORG | E75: -70 | F75: 0 | G75: =E75 -> -70 | H75: mat i samband med supa | L75: Regular
A76: 2015 | B76: 11 | C76: 26 | D76: Harrys G¦teborg G¦teborg | E76: -69 | F76: 0 | G76: =E76 -> -69 | H76: mat i samband med supa | L76: Regular
A77: 2015 | B77: 11 | C77: 26 | D77: Harrys G¦teborg G¦teborg | E77: -65 | F77: 0 | G77: =E77 -> -65 | H77: mat i samband med supa | L77: Regular
... A127: 2015 | B127: 10 | C127: 30 | D127: BAHNHOF | E127: -841 | F127: 0 | G127: =E127 -> -841 | H127: internet | L127: Regular
A128: 2015 | B128: 10 | C128: 30 | D128: 47516877 | E128: 1000 | F128: 0 | G128: =E128 -> 1000 | H128: spara till amortering | L128: Regular
A129: 2015 | B129: 10 | C129: 29 | D129: SV INGENJ | E129: -320 | F129: 0 | G129: =E129 -> -320 | H129: si och akassa | L129: Regular
A130: 2015 | B130: 10 | C130: 29 | D130: SILVIS RESTAURANG GOTEBORG | E130: -880 | F130: 0 | G130: =E130 -> -880 | H130: nöjes utemat | L130: Regular
A131: 2015 | B131: 10 | C131: 29 | D131: OLREPUBLIKEN GOTEBORG | E131: -95 | F131: 0 | G131: =E131 -> -95 | H131: lunch utemat | L131: Regular
A132: 2015 | B132: 10 | C132: 29 | D132: MAIDEN JG | E132: 670 | F132: 0 | G132: =E132 -> 670 | H132: spara till russel övrigt | L132: Regular
A133: 2015 | B133: 10 | C133: 29 | D133: iZ *Blixten Co A Stockholm | E133: -40 | F133: 0 | G133: =E133 -> -40 | H133: spara almänt | L133: Regular
...

Sheet Budget (2015)
B1: Allkonto, plus annat | C1: ' 629 011 192 | F1: Löne | G1: Kontonummer: | H1: ' 629010552 | J1: Clearing HB | K1: ' 6241
B2: Senaste uppdaterad | C2: Idag | D2: Uppd.historik | F2: =CONCATENATE(G8," ",F8) -> Kontoutdrag FEL! 81545,8099999998 | H2: Statad troligt | I2: 38201 | X2: y | Y2: m | Z2: d | AA2: n | AB2: t | AC2: g | AD2: s | AE2: b | AI2: c
B3: 42270 | C3: =TODAY() -> 46136 | D3: (eg. 2009-08-22 - 23), 2009-08-23, 2009-03-26, 2010-07-28 | F3: =F12 -> FEL! | G3: =G13 -> 81111.81 | H3: =F12 -> FEL! | I3: =F12 -> FEL! | J3: =F12 -> FEL! | K3: =F12 -> FEL! | L3: =F12 -> FEL! | M3: =F12 -> FEL! | N3: =F12 -> FEL! | O3: =F12 -> FEL! | P3: =F12 -> FEL! | Q3: =F12 -> FEL! | R3: =F12 -> FEL! | AI3: Regular
B4: Russel/vecka | C4: =D17 -> -2798.0773 | D4: =D15 -> -2798.0773 | G4: =IF(NOT(ROUND(G13,0)=0),G13,"") -> 81111.81 | H4: =IF(G4="","",H13) -> <= detta felar
C6: år | D6: =VALUE(LEFT(RIGHT(sheetname(B1),LEN(sheetname(B1))-SEARCH("(",sheetname(B1),1)),SEARCH(")",sheetname(B1),1)-(1+SEARCH("(",sheetname(B1),1)))) -> #NAME? | E6: (Kvar ref) | F6: Från tidigare | G6: Januari | H6: Februari | I6: Mars | J6: April | K6: Maj | L6: Juni | M6: Juli | N6: Augusti | O6: September | P6: Oktober | Q6: November | R6: December | S6: Summa
B7: Temp (kompensera för utlägg på Lönkonto) | C7: 0 | F7: Betalade kreditfakturor | G7: =0 -> 0 | H7: Saldo Allkonto: | I7: Saldo: | J7: =Kontoutdrag_officiella!N1+0 -> 0 | R7: Saldo Lönekonto: | S7: =Kontoutdrag_officiella!M1+0 -> 0 | U7: : Saldo Lönekonto:
B8: på konto VERKLIGA | C8: =J7+C7+S8 -> -2500 | D8: Utan lägga undan | F8: =C8-C9-J12 -> 81545.81 | G8: =IF((ROUND((F8),2))=0,"Kontoutdrag Stämmer","Kontoutdrag FEL!") -> Kontoutdrag FEL! | I8: Ej fakturerat: | J8: =Kontoutdrag_officiella!O1+0 -> 0 | S8: =S7-2500 -> -2500
B9: Bör vara | C9: =DSUM(Kontoutdrag_officiella!$A:$L,"t",X2:AI3) -> -84045.81 | D9: =C8-C9 -> 81545.81 | F9: <--Ev. Fel | I9: Fakturerat, ej förfallet: | J9: =Kontoutdrag_officiella!P1+0 -> 0
B10: Lägga undan | C10: =S144+1000 -> -83611.81 | D10: =C9-C10 -> -434 | F10: =#REF! -> #REF! | G10: UtLånat | I10: Ofakturerade transaktioner: | J10: 0
C11: Stulet-> | D11: =D9-J12+G7 -> 81545.81 | G11: Kredit ej betald | I11: Fakturerat ej förfallet: | J11: 0
B12: Kvar | C12: =C8-C10 -> 81111.81 | D12: <----------------------- | F12: =IF((ROUND((G12-C12),2))=0,"Stämmer","FEL!") -> FEL! | G12: =J12 -> 0 | H12: =stämmer? | I12: =IF((ROUND((G12-C12),2))=0,"Stämmer","FEL!") -> FEL! | J12: =-1*SUM(J8:J11) -> 0
C13: =C8-G12 -> -2500 | D13: <--Detta är så mycket som finns att spendera | G13: =C12-G12 -> 81111.81 | H13: <= detta felar
C14: Bara a | D14: Både r o a
B15: Russel Kvar | C15: =V160 -> -7027.3173 | D15: =V142 -> -2798.0773 | G15: Pengar in, datum: | H15: 38985 | I15: 39015 | J15: 39045 | K15: 39073 | M15: 39136 | N15: 38799 | O15: 38832 | P15: 38862 | W15: Med sparat
B16: Me kontant | C16: =C15 -> -7027.3173 | D16: =D15 -> -2798.0773 | F16: Idag | G16: Pengar in | H16: Dagar kvar | I16: Veckor kvar | J16: Avrundade Veckor | L16: Eget Val av veckor kvar | N16: 1850/4= | P16: dagar i månaden | S16: Russel | U16: veckor | V16: per vecka | W16: =S17-500*2 -> 131.72
B17: Russel/vecka | C17: =C15/J17 -> -7027.3173 | D17: =D15/J17 -> -2798.0773 | F17: =DAY(TODAY()) -> 24 | G17: 25 | H17: =G17-(IF((G17-F17)<1,IF(F17-G17,F17-P17,F17-P17),F17)) -> 1 | I17: =H17/7 -> 0.14285714 | J17: =ROUNDUP(I17,0) -> 1 | L17: 5 | M17: =D15/L17 -> -559.61545 | N17: =1850/4 -> 462.5 | P17: 31 | S17: =C48 -> 1131.72 | U17: 4.5 | V17: =S17/U17 -> 251.49333 | W17: =W16/U17 -> 29.271111
B18: (Exakt) | C18: =C15/I17 -> -49191.221 | D18: =D15/I17 -> -19586.541 | F18: Kr om dan | G18: =D15/H17 -> -2798.0773 | H18: veckodag | I18: =D15/(I17*5) -> -3917.3082
I19: Ovan fungerar enl. följande, det som finns på konot pytsas ut till olika potter, sen när inkomst kommer så drar man av det och sätter det på nästa månads pyttsar, så det blir en illusion av förskjutning, men allt är i sin ordning för lönen används till nä | S19: Tot ^ | U19: Per mån ^
C20: =C13-C10 -> 81111.81
B21: Buffert, som lönekvot | C21: =C10/C62 -> -2.8781044 | F21: Antalet arbetsdagar under ett år skiftar mellan 224 och 229 beroende på
C22: =C8/C62 -> -0.086055557 | D22: =(C8+10000+20000)/C62 -> 0.94661113 | E22: =SUM(E40:E42)/SUM(C40:C41) -> -5.0599239
A23: In | B23: IN | C23: IN | D23: IN | F23: IN | G23: IN | H23: IN | I23: IN | J23: IN | K23: IN | L23: IN | M23: IN | N23: IN | O23: IN | P23: IN | Q23: IN | R23: IN | S23: IN | W23: Dra in
A24: In | C24: Ändra helst bara varje år | D24: Kompensation av felgissade potter | E24: Kvar ref
A25: In | B25: hyra (inkl. 1k amortering) | C25: =3851+5742+1205+37-635-1250+3333 -> 12283 | E25: =S111 -> -32357 | F25: ='Budget (2014)'!S111+D25 -> 21176.6 | G25: =3851+5742+1205+37-635-1250+3333 -> 12283 | H25: =3851+5742+1205+37-635-1250+3333 -> 12283 | I25: =3851+5742+1205+37-635-1250+3333 -> 12283 | J25: =3851+5742+1205+37-635-1250+3333 -> 12283 | K25: =3851+5742+1205+37-635-1250+3333 -> 12283 | L25: =3851+5742+1205+37-635-1250+3333 -> 12283 | M25: =3851+5742+1205+37-635-1250+3333 -> 12283 | N25: =3851+5742+1205+37-635-1250+3333 -> 12283 | ... R25: =3851+5742+1205+37-635-1250+3333 -> 12283 | S25: =SUM(G25:R25) -> 147396 | T25: hyra (inkl. 1k amortering)
A26: In | B26: si och akassa | C26: =-50+720/2+4+4+2 -> 320 | E26: =S112 -> 0 | F26: ='Budget (2014)'!S112+D26 -> 0 | G26: =-50+720/2+4+4+2 -> 320 | H26: =-50+720/2+4+4+2 -> 320 | I26: =-50+720/2+4+4+2 -> 320 | J26: =-50+720/2+4+4+2 -> 320 | K26: =-50+720/2+4+4+2 -> 320 | L26: =-50+720/2+4+4+2 -> 320 | M26: =-50+720/2+4+4+2 -> 320 | N26: =-50+720/2+4+4+2 -> 320 | ... R26: =-50+720/2+4+4+2 -> 320 | S26: =SUM(G26:R26) -> 3840 | T26: si och akassa
A27: In | B27: hemförsäkring | C27: =108+11 -> 119 | E27: =S113 -> -406 | F27: ='Budget (2014)'!S113+D27 -> -46 | G27: =108+11 -> 119 | H27: =108+11 -> 119 | I27: =108+11 -> 119 | J27: =108+11 -> 119 | K27: =108+11 -> 119 | L27: =108+11 -> 119 | M27: =108+11 -> 119 | N27: =108+11 -> 119 | ... R27: =108+11 -> 119 | S27: =SUM(G27:R27) -> 1428 | T27: hemförsäkring
A28: In | B28: liv- o sjukförsäkring etc | C28: 280 | E28: =S114 -> -349 | F28: ='Budget (2014)'!S114+D28 -> -78 | G28: 280 | H28: 280 | I28: 280 | J28: 280 | K28: 280 | L28: 280 | M28: 280 | N28: 280 | O28: 280 | P28: 280 | Q28: 280 | R28: 280 | S28: =SUM(G28:R28) -> 3360 | T28: liv- o sjukförsäkring etc | W28: =R28 -> 280
A29: In | B29: stockholms stads bostadskö | C29: =225/12 -> 18.75 | E29: =S115 -> 225 | F29: ='Budget (2014)'!S115+D29 -> 0 | G29: =225/12 -> 18.75 | H29: =225/12 -> 18.75 | I29: =225/12 -> 18.75 | J29: =225/12 -> 18.75 | K29: =225/12 -> 18.75 | L29: =225/12 -> 18.75 | M29: =225/12 -> 18.75 | N29: =225/12 -> 18.75 | ... R29: =225/12 -> 18.75 | S29: =SUM(G29:R29) -> 225 | T29: stockholms stads bostadskö
A30: In | B30: csn | C30: =(0*(1000+(216/3))+((120+12923)/12))*0+(120+2917+3037*2+3035)/12 -> 1012.1667 | E30: =S116 -> -89 | F30: ='Budget (2014)'!S116+D30 -> 18 | G30: =(0*(1000+(216/3))+((120+12923)/12))*0+(120+2917+3037*2+3035)/12 -> 1012.1667 | H30: =(0*(1000+(216/3))+((120+12923)/12))*0+(120+2917+3037*2+3035)/12 -> 1012.1667 | I30: =(0*(1000+(216/3))+((120+12923)/12))*0+(120+2917+3037*2+3035)/12 -> 1012.1667 | J30: =(0*(1000+(216/3))+((120+12923)/12))*0+(120+2917+3037*2+3035)/12 -> 1012.1667 | K30: =(0*(1000+(216/3))+((120+12923)/12))*0+(120+2917+3037*2+3035)/12 -> 1012.1667 | L30: =(0*(1000+(216/3))+((120+12923)/12))*0+(120+2917+3037*2+3035)/12 -> 1012.1667 | M30: =(0*(1000+(216/3))+((120+12923)/12))*0+(120+2917+3037*2+3035)/12 -> 1012.1667 | N30: =(0*(1000+(216/3))+((120+12923)/12))*0+(120+2917+3037*2+3035)/12 -> 1012.1667 | ... R30: =(0*(1000+(216/3))+((120+12923)/12))*0+(120+2917+3037*2+3035)/12 -> 1012.1667 | S30: =SUM(G30:R30) -> 12146 | T30: csn
A31: In | B31: röda korset | C31: =100+50 -> 150 | E31: =S117 -> -1874 | F31: ='Budget (2014)'!S117+D31 -> 600 | G31: =100+50 -> 150 | H31: =100+50 -> 150 | I31: =100+50 -> 150 | J31: =100+50 -> 150 | K31: =100+50 -> 150 | L31: =100+50 -> 150 | M31: =100+50 -> 150 | N31: =100+50 -> 150 | ... R31: =100+50 -> 150 | S31: =SUM(G31:R31) -> 1800 | T31: röda korset
A32: In | B32: el | C32: =0*355.9+200 -> 200 | E32: =S118 -> 533 | F32: ='Budget (2014)'!S118+D32 -> 373 | G32: =0*355.9+200 -> 200 | H32: =0*355.9+200 -> 200 | I32: =0*355.9+200 -> 200 | J32: =0*355.9+200 -> 200 | K32: =0*355.9+200 -> 200 | L32: =0*355.9+200 -> 200 | M32: =0*355.9+200 -> 200 | N32: =0*355.9+200 -> 200 | ... R32: =0*355.9+200 -> 200 | S32: =SUM(G32:R32) -> 2400 | T32: el
A33: In | B33: internet | C33: =188*0+299 -> 299 | E33: =S119 -> -1710 | F33: ='Budget (2014)'!S119+D33 -> 0 | G33: =188*0+299 -> 299 | H33: =188*0+299 -> 299 | I33: =188*0+299 -> 299 | J33: =188*0+299 -> 299 | K33: =188*0+299 -> 299 | L33: =188*0+299 -> 299 | M33: =188*0+299 -> 299 | N33: =188*0+299 -> 299 | ... R33: =188*0+299 -> 299 | S33: =SUM(G33:R33) -> 3588 | T33: internet
A34: In | B34: telefonsamtal | C34: =(39+69+120)*0+(299+15+40)*0+339*0+(354-339)*0+220+299-50+50 -> 519 | E34: =S120 -> 5914 | F34: ='Budget (2014)'!S120+D34 -> 255 | G34: =(39+69+120)*0+(299+15+40)*0+339*0+(354-339)*0+220+299-50+50 -> 519 | H34: =(39+69+120)*0+(299+15+40)*0+339*0+(354-339)*0+220+299-50+50 -> 519 | I34: =(39+69+120)*0+(299+15+40)*0+339*0+(354-339)*0+220+299-50+50 -> 519 | J34: =(39+69+120)*0+(299+15+40)*0+339*0+(354-339)*0+220+299-50+50 -> 519 | K34: =(39+69+120)*0+(299+15+40)*0+339*0+(354-339)*0+220+299-50+50 -> 519 | L34: =(39+69+120)*0+(299+15+40)*0+339*0+(354-339)*0+220+299-50+50 -> 519 | M34: =(39+69+120)*0+(299+15+40)*0+339*0+(354-339)*0+220+299-50+50 -> 519 | N34: =(39+69+120)*0+(299+15+40)*0+339*0+(354-339)*0+220+299-50+50 -> 519 | ... R34: =(39+69+120)*0+(299+15+40)*0+339*0+(354-339)*0+220+299-50+50 -> 519 | S34: =SUM(G34:R34) -> 6228 | T34: telefonsamtal | W34: =R34-40 -> 479
A35: In | B35: hygien (disk, tvätt o tvål etc) | C35: =20+10 -> 30 | E35: =S121 -> 720 | F35: ='Budget (2014)'!S121+D35 -> 360 | G35: =20+10 -> 30 | H35: =20+10 -> 30 | I35: =20+10 -> 30 | J35: =20+10 -> 30 | K35: =20+10 -> 30 | L35: =20+10 -> 30 | M35: =20+10 -> 30 | N35: =20+10 -> 30 | ... R35: =20+10 -> 30 | S35: =SUM(G35:R35) -> 360 | T35: hygien (disk, tvätt o tvål etc)
A36: In | B36: hemlagad mat | C36: =850+50-300 -> 600 | E36: =S122 -> 3509.24 | F36: ='Budget (2014)'!S122+D36 -> 3492.93 | G36: =850+50-300 -> 600 | H36: =850+50-300 -> 600 | I36: =850+50-300 -> 600 | J36: =850+50-300 -> 600 | K36: =850+50-300 -> 600 | L36: =850+50-300 -> 600 | M36: =850+50-300 -> 600 | N36: =850+50-300 -> 600 | ... R36: =850+50-300 -> 600 | S36: =SUM(G36:R36) -> 7200 | T36: hemlagad mat
A37: In | B37: hemlagad lunch | C37: =(226/12)*(15+20)*0.5*0+50*0 -> 0 | E37: =S123 -> 0 | F37: ='Budget (2014)'!S123+D37 -> 0 | G37: =(226/12)*(15+20)*0.5*0+50*0 -> 0 | H37: =(226/12)*(15+20)*0.5*0+50*0 -> 0 | I37: =(226/12)*(15+20)*0.5*0+50*0 -> 0 | J37: =(226/12)*(15+20)*0.5*0+50*0 -> 0 | K37: =(226/12)*(15+20)*0.5*0+50*0 -> 0 | L37: =(226/12)*(15+20)*0.5*0+50*0 -> 0 | M37: =(226/12)*(15+20)*0.5*0+50*0 -> 0 | N37: =(226/12)*(15+20)*0.5*0+50*0 -> 0 | ... R37: =(226/12)*(15+20)*0.5*0+50*0 -> 0 | S37: =SUM(G37:R37) -> 0 | T37: hemlagad lunch
A38: In | B38: lunch utemat | C38: =((780/11)*227)/12+10*10 -> 1441.3636 | E38: =S124 -> 4211.7273 | F38: ='Budget (2014)'!S124+D38 -> 2622.3636 | G38: =((780/11)*227)/12+10*10 -> 1441.3636 | H38: =((780/11)*227)/12+10*10 -> 1441.3636 | I38: =((780/11)*227)/12+10*10 -> 1441.3636 | J38: =((780/11)*227)/12+10*10 -> 1441.3636 | K38: =((780/11)*227)/12+10*10 -> 1441.3636 | L38: =((780/11)*227)/12+10*10 -> 1441.3636 | M38: =((780/11)*227)/12+10*10 -> 1441.3636 | N38: =((780/11)*227)/12+10*10 -> 1441.3636 | ... R38: =((780/11)*227)/12+10*10 -> 1441.3636 | S38: =SUM(G38:R38) -> 17296.364 | T38: lunch utemat | V38: russel tot | W38: =R38-45 -> 1396.3636
A39: In | B39: nöjes utemat | C39: =(300*2+250*2)*0+(900+500)*1+0*(45*5*4.5+450)+800-100 -> 2100 | E39: =S125 -> 7655.21 | F39: ='Budget (2014)'!S125+D39 -> 7804.36 | G39: =(300*2+250*2)*0+(900+500)*1+0*(45*5*4.5+450)+800-100 -> 2100 | H39: =(300*2+250*2)*0+(900+500)*1+0*(45*5*4.5+450)+800-100 -> 2100 | I39: =(300*2+250*2)*0+(900+500)*1+0*(45*5*4.5+450)+800-100 -> 2100 | J39: =(300*2+250*2)*0+(900+500)*1+0*(45*5*4.5+450)+800-100 -> 2100 | K39: =(300*2+250*2)*0+(900+500)*1+0*(45*5*4.5+450)+800-100 -> 2100 | L39: =(300*2+250*2)*0+(900+500)*1+0*(45*5*4.5+450)+800-100 -> 2100 | M39: =(300*2+250*2)*0+(900+500)*1+0*(45*5*4.5+450)+800-100 -> 2100 | N39: =(300*2+250*2)*0+(900+500)*1+0*(45*5*4.5+450)+800-100 -> 2100 | ... R39: =(300*2+250*2)*0+(900+500)*1+0*(45*5*4.5+450)+800-100 -> 2100 | S39: =SUM(G39:R39) -> 25200 | T39: nöjes utemat | V39: =C39+C40+C41+C42+C43+C52+C55+C56 -> 4274.9997
A40: In | B40: mat i samband med supa | C40: =2*250*0+1477.49969696969 -> 1477.4997 | E40: =S126 -> -6552.3673 | F40: ='Budget (2014)'!S126+D40 -> 7266.1964 | G40: =2*250*0+1477.49969696969 -> 1477.4997 | H40: =2*250*0+1477.49969696969 -> 1477.4997 | I40: =2*250*0+1477.49969696969 -> 1477.4997 | J40: =2*250*0+1477.49969696969 -> 1477.4997 | K40: =2*250*0+1477.49969696969 -> 1477.4997 | L40: =2*250*0+1477.49969696969 -> 1477.4997 | M40: =2*250*0+1477.49969696969 -> 1477.4997 | N40: =2*250*0+1477.49969696969 -> 1477.4997 | ... R40: =2*250*0+1477.49969696969 -> 1477.4997 | S40: =SUM(G40:R40) -> 17729.996 | T40: mat i samband med supa | W40: =R40-50 -> 1427.4997 | X40: =17-14 -> 3
A41: In | B41: alkohol | C41: =500*2-1000+4.5*55 -> 247.5 | E41: =S127 -> -1188 | F41: ='Budget (2014)'!S127+D41 -> -1699 | G41: =500*2-1000+4.5*55 -> 247.5 | H41: =500*2-1000+4.5*55 -> 247.5 | I41: =500*2-1000+4.5*55 -> 247.5 | J41: =500*2-1000+4.5*55 -> 247.5 | K41: =500*2-1000+4.5*55 -> 247.5 | L41: =500*2-1000+4.5*55 -> 247.5 | M41: =500*2-1000+4.5*55 -> 247.5 | N41: =500*2-1000+4.5*55 -> 247.5 | ... R41: =500*2-1000+4.5*55 -> 247.5 | S41: =SUM(G41:R41) -> 2970 | T41: alkohol | W41: =R41-50 -> 197.5
...

Sheet Villkor 1 år (2015)
A1: y | B1: m | D1: d | E1: n | F1: e | G1: t | J1: b | L1: år | M1: =2015 -> 2015 | N1: Steg mellan varje | O1: =21-1 -> 20
A2: =$M$1 -> 2015 | B2: 1 | J2: hyra (inkl. 1k amortering)
A3: y | B3: m | D3: d | E3: n | F3: e | G3: t | J3: b
A4: =$M$1 -> 2015 | B4: 1 | J4: si och akassa
A5: y | B5: m | D5: d | E5: n | F5: e | G5: t | J5: b
A6: =$M$1 -> 2015 | B6: 1 | J6: hemförsäkring
A7: y | B7: m | D7: d | E7: n | F7: e | G7: t | J7: b
A8: =$M$1 -> 2015 | B8: 1 | J8: liv- o sjukförsäkring etc
A9: y | B9: m | D9: d | E9: n | F9: e | G9: t | J9: b
A10: =$M$1 -> 2015 | B10: 1 | J10: stockholms stads bostadskö
A11: y | B11: m | D11: d | E11: n | F11: e | G11: t | J11: b
A12: =$M$1 -> 2015 | B12: 1 | J12: csn
A13: y | B13: m | D13: d | E13: n | F13: e | G13: t | J13: b
A14: =$M$1 -> 2015 | B14: 1 | J14: röda korset
A15: y | B15: m | D15: d | E15: n | F15: e | G15: t | J15: b
A16: =$M$1 -> 2015 | B16: 1 | J16: el
A17: y | B17: m | D17: d | E17: n | F17: e | G17: t | J17: b
A18: =$M$1 -> 2015 | B18: 1 | J18: internet
A19: y | B19: m | D19: d | E19: n | F19: e | G19: t | J19: b
A20: =$M$1 -> 2015 | B20: 1 | J20: telefonsamtal
A21: y | B21: m | D21: d | E21: n | F21: e | G21: t | J21: b
A22: =$M$1 -> 2015 | B22: 1 | J22: hygien (disk, tvätt o tvål etc)
A23: y | B23: m | D23: d | E23: n | F23: e | G23: t | J23: b
A24: =$M$1 -> 2015 | B24: 1 | J24: hemlagad mat
A25: y | B25: m | D25: d | E25: n | F25: e | G25: t | J25: b
A26: =$M$1 -> 2015 | B26: 1 | J26: hemlagad lunch
A27: y | B27: m | D27: d | E27: n | F27: e | G27: t | J27: b
A28: =$M$1 -> 2015 | B28: 1 | J28: lunch utemat
A29: y | B29: m | D29: d | E29: n | F29: e | G29: t | J29: b
A30: =$M$1 -> 2015 | B30: 1 | J30: nöjes utemat
A31: y | B31: m | D31: d | E31: n | F31: e | G31: t | J31: b
A32: =$M$1 -> 2015 | B32: 1 | J32: mat i samband med supa
A33: y | B33: m | D33: d | E33: n | F33: e | G33: t | J33: b
A34: =$M$1 -> 2015 | B34: 1 | J34: alkohol
A35: y | B35: m | D35: d | E35: n | F35: e | G35: t | J35: b
A36: =$M$1 -> 2015 | B36: 1 | J36: taxi efter supa
A37: y | B37: m | D37: d | E37: n | F37: e | G37: t | J37: b
A38: =$M$1 -> 2015 | B38: 1 | J38: Buss etc i samband med supa
A39: y | B39: m | D39: d | E39: n | F39: e | G39: t | J39: b
A40: =$M$1 -> 2015 | B40: 1 | J40: oväntade utgifter
...

Sheet Budget (2014)
B1: Allkonto, plus annat | C1: ' 629 011 192 | F1: Löne | G1: Kontonummer: | H1: ' 629010552 | J1: Clearing HB | K1: ' 6241
B2: Senaste uppdaterad | C2: Idag | D2: Uppd.historik | F2: =CONCATENATE(G8," ",F8) -> Kontoutdrag FEL! 81545,8099999998 | H2: Statad troligt | I2: 38201 | X2: y | Y2: m | Z2: d | AA2: n | AB2: t | AC2: g | AD2: s | AE2: b | AI2: c
B3: 41905 | C3: =TODAY() -> 46136 | D3: (eg. 2009-08-22 - 23), 2009-08-23, 2009-03-26, 2010-07-28 | F3: =F12 -> FEL! | G3: =G13 -> -77216.82 | H3: =F12 -> FEL! | I3: =F12 -> FEL! | J3: =F12 -> FEL! | K3: =F12 -> FEL! | L3: =F12 -> FEL! | M3: =F12 -> FEL! | N3: =F12 -> FEL! | O3: =F12 -> FEL! | P3: =F12 -> FEL! | Q3: =F12 -> FEL! | R3: =F12 -> FEL! | AI3: Regular
B4: Russel/vecka | C4: =D17 -> 16186.486 | D4: =D15 -> 16186.486 | G4: =IF(NOT(ROUND(G13,0)=0),G13,"") -> -77216.82 | H4: =IF(G4="","",H13) -> <= detta felar
C6: år | D6: =VALUE(LEFT(RIGHT(sheetname(B1),LEN(sheetname(B1))-SEARCH("(",sheetname(B1),1)),SEARCH(")",sheetname(B1),1)-(1+SEARCH("(",sheetname(B1),1)))) -> #NAME? | E6: (Kvar ref) | F6: Från tidigare | G6: Januari | H6: Februari | I6: Mars | J6: April | K6: Maj | L6: Juni | M6: Juli | N6: Augusti | O6: September | P6: Oktober | Q6: November | R6: December | S6: Summa
B7: Temp (kompensera för utlägg på Lönkonto) | C7: 0 | F7: Betalade kreditfakturor | G7: =0 -> 0 | H7: Saldo Allkonto: | I7: Saldo: | J7: =Kontoutdrag_officiella!N1+0 -> 0 | R7: Saldo Lönekonto: | S7: =Kontoutdrag_officiella!M1+0 -> 0 | U7: : Saldo Lönekonto:
B8: på konto VERKLIGA | C8: =J7+C7+S8 -> -2500 | D8: Utan lägga undan | F8: =C8-C9-J12 -> 81545.81 | G8: =IF((ROUND((F8),2))=0,"Kontoutdrag Stämmer","Kontoutdrag FEL!") -> Kontoutdrag FEL! | I8: Ej fakturerat: | J8: =Kontoutdrag_officiella!O1+0 -> 0 | S8: =S7-2500 -> -2500
B9: Bör vara | C9: =DSUM(Kontoutdrag_officiella!$A:$L,"t",X2:AI3) -> -84045.81 | D9: =C8-C9 -> 81545.81 | F9: <--Ev. Fel | I9: Fakturerat, ej förfallet: | J9: =Kontoutdrag_officiella!P1+0 -> 0
B10: Lägga undan | C10: =S144+1000 -> 74716.82 | D10: =C9-C10 -> -158762.63 | F10: =#REF! -> #REF! | G10: UtLånat | I10: Ofakturerade transaktioner: | J10: 0
C11: Stulet-> | D11: =D9-J12+G7 -> 81545.81 | G11: Kredit ej betald | I11: Fakturerat ej förfallet: | J11: 0
B12: Kvar | C12: =C8-C10 -> -77216.82 | D12: <----------------------- | F12: =IF((ROUND((G12-C12),2))=0,"Stämmer","FEL!") -> FEL! | G12: =J12 -> 0 | H12: =stämmer? | I12: =IF((ROUND((G12-C12),2))=0,"Stämmer","FEL!") -> FEL! | J12: =-1*SUM(J8:J11) -> 0
C13: =C8-G12 -> -2500 | D13: <--Detta är så mycket som finns att spendera | G13: =C12-G12 -> -77216.82 | H13: <= detta felar
C14: Bara a | D14: Både r o a
B15: Russel Kvar | C15: =V160 -> 12333.556 | D15: =V142 -> 16186.486 | G15: Pengar in, datum: | H15: 38985 | I15: 39015 | J15: 39045 | K15: 39073 | M15: 39136 | N15: 38799 | O15: 38832 | P15: 38862 | W15: Med sparat
B16: Me kontant | C16: =C15 -> 12333.556 | D16: =D15 -> 16186.486 | F16: Idag | G16: Pengar in | H16: Dagar kvar | I16: Veckor kvar | J16: Avrundade Veckor | L16: Eget Val av veckor kvar | N16: 1850/4= | P16: dagar i månaden | S16: Russel | U16: veckor | V16: per vecka | W16: =S17-500*2 -> 131.72
B17: Russel/vecka | C17: =C15/J17 -> 12333.556 | D17: =D15/J17 -> 16186.486 | F17: =DAY(TODAY()) -> 24 | G17: 25 | H17: =G17-(IF((G17-F17)<1,IF(F17-G17,F17-P17,F17-P17),F17)) -> 1 | I17: =H17/7 -> 0.14285714 | J17: =ROUNDUP(I17,0) -> 1 | L17: 5 | M17: =D15/L17 -> 3237.2973 | N17: =1850/4 -> 462.5 | P17: 31 | S17: =C48 -> 1131.72 | U17: 4.5 | V17: =S17/U17 -> 251.49333 | W17: =W16/U17 -> 29.271111
B18: (Exakt) | C18: =C15/I17 -> 86334.895 | D18: =D15/I17 -> 113305.4 | F18: Kr om dan | G18: =D15/H17 -> 16186.486 | H18: veckodag | I18: =D15/(I17*5) -> 22661.081
I19: Ovan fungerar enl. följande, det som finns på konot pytsas ut till olika potter, sen när inkomst kommer så drar man av det och sätter det på nästa månads pyttsar, så det blir en illusion av förskjutning, men allt är i sin ordning för lönen används till nä | S19: Tot ^ | U19: Per mån ^
C20: =C13-C10 -> -77216.82
B21: Buffert, som lönekvot | C21: =C10/C62 -> 2.571919 | F21: Antalet arbetsdagar under ett år skiftar mellan 224 och 229 beroende på
C22: =C8/C62 -> -0.086055557 | D22: =(C8+10000+20000)/C62 -> 0.94661113 | E22: =SUM(E40:E42)/SUM(C40:C41) -> 2.9444622
A23: In | B23: IN | C23: IN | D23: IN | F23: IN | G23: IN | H23: IN | I23: IN | J23: IN | K23: IN | L23: IN | M23: IN | N23: IN | O23: IN | P23: IN | Q23: IN | R23: IN | S23: IN | W23: Dra in
A24: In | C24: Ändra helst bara varje år | D24: Kompensation av felgissade potter | E24: Kvar ref
A25: In | B25: hyra (inkl. 1k amortering) | C25: =3851+5742+1205+37-635-1250+3333 -> 12283 | E25: =S111 -> 21176.6 | F25: =0+D25 -> 0 | G25: =3851+5742+1205+37-635-1250+3333 -> 12283 | H25: =3851+5742+1205+37-635-1250+3333 -> 12283 | I25: =3851+5742+1205+37-635-1250+3333 -> 12283 | J25: =3851+5742+1205+37-635-1250+3333 -> 12283 | K25: =3851+5742+1205+37-635-1250+3333 -> 12283 | L25: =3851+5742+1205+37-635-1250+3333 -> 12283 | M25: =3851+5742+1205+37-635-1250+3333 -> 12283 | N25: 12283 | O25: =3851+5742+1205+37-635-1250+3333 -> 12283 | P25: 12283 | Q25: =3851+5742+1205+37-635-1250+3333 -> 12283 | R25: 12283 | S25: =SUM(G25:R25) -> 147396 | T25: hyra (inkl. 1k amortering)
A26: In | B26: si och akassa | C26: =-50+720/2+4+4+2 -> 320 | E26: =S112 -> 0 | F26: =0+D26 -> 0 | G26: =-50+720/2+4+4+2 -> 320 | H26: =-50+720/2+4+4+2 -> 320 | I26: =-50+720/2+4+4+2 -> 320 | J26: =-50+720/2+4+4+2 -> 320 | K26: =-50+720/2+4+4+2 -> 320 | L26: =-50+720/2+4+4+2 -> 320 | M26: =-50+720/2+4+4+2 -> 320 | N26: 320 | O26: =-50+720/2+4+4+2 -> 320 | P26: 320 | Q26: =-50+720/2+4+4+2 -> 320 | R26: 320 | S26: =SUM(G26:R26) -> 3840 | T26: si och akassa
A27: In | B27: hemförsäkring | C27: =108+11 -> 119 | E27: =S113 -> -46 | F27: =0+D27 -> 0 | G27: =108+11 -> 119 | H27: =108+11 -> 119 | I27: =108+11 -> 119 | J27: =108+11 -> 119 | K27: =108+11 -> 119 | L27: =108+11 -> 119 | M27: =108+11 -> 119 | N27: 119 | O27: =108+11 -> 119 | P27: 119 | Q27: =108+11 -> 119 | R27: 119 | S27: =SUM(G27:R27) -> 1428 | T27: hemförsäkring
A28: In | B28: liv- o sjukförsäkring etc | C28: 280 | E28: =S114 -> -78 | F28: =0+D28 -> 0 | G28: 280 | H28: 280 | I28: 280 | J28: 280 | K28: 280 | L28: 280 | M28: 280 | N28: 280 | O28: 280 | P28: 280 | Q28: 280 | R28: 280 | S28: =SUM(G28:R28) -> 3360 | T28: liv- o sjukförsäkring etc | W28: =R28 -> 280
A29: In | B29: stockholms stads bostadskö | C29: =225/12 -> 18.75 | E29: =S115 -> 0 | F29: =0+D29 -> 0 | G29: =225/12 -> 18.75 | H29: =225/12 -> 18.75 | I29: =225/12 -> 18.75 | J29: =225/12 -> 18.75 | K29: =225/12 -> 18.75 | L29: =225/12 -> 18.75 | M29: =225/12 -> 18.75 | N29: 18.75 | O29: =225/12 -> 18.75 | P29: 18.75 | Q29: =225/12 -> 18.75 | R29: 18.75 | S29: =SUM(G29:R29) -> 225 | T29: stockholms stads bostadskö
A30: In | B30: csn | C30: =(0*(1000+(216/3))+((120+12923)/12))*0+(120+2917+3037*2+3035)/12 -> 1012.1667 | E30: =S116 -> 18 | F30: =0+D30 -> 0 | G30: =(0*(1000+(216/3))+((120+12923)/12))*0+(120+2917+3037*2+3035)/12 -> 1012.1667 | H30: =(0*(1000+(216/3))+((120+12923)/12))*0+(120+2917+3037*2+3035)/12 -> 1012.1667 | I30: =(0*(1000+(216/3))+((120+12923)/12))*0+(120+2917+3037*2+3035)/12 -> 1012.1667 | J30: =(0*(1000+(216/3))+((120+12923)/12))*0+(120+2917+3037*2+3035)/12 -> 1012.1667 | K30: =(0*(1000+(216/3))+((120+12923)/12))*0+(120+2917+3037*2+3035)/12 -> 1012.1667 | L30: =(0*(1000+(216/3))+((120+12923)/12))*0+(120+2917+3037*2+3035)/12 -> 1012.1667 | M30: =(0*(1000+(216/3))+((120+12923)/12))*0+(120+2917+3037*2+3035)/12 -> 1012.1667 | N30: 1012.1667 | O30: =(0*(1000+(216/3))+((120+12923)/12))*0+(120+2917+3037*2+3035)/12 -> 1012.1667 | P30: 1012.1667 | Q30: =(0*(1000+(216/3))+((120+12923)/12))*0+(120+2917+3037*2+3035)/12 -> 1012.1667 | R30: 1012.1667 | S30: =SUM(G30:R30) -> 12146 | T30: csn
A31: In | B31: röda korset | C31: =100+50 -> 150 | E31: =S117 -> 600 | F31: =0+D31 -> 0 | G31: =100+50 -> 150 | H31: =100+50 -> 150 | I31: =100+50 -> 150 | J31: =100+50 -> 150 | K31: =100+50 -> 150 | L31: =100+50 -> 150 | M31: =100+50 -> 150 | N31: 150 | O31: =100+50 -> 150 | P31: 150 | Q31: =100+50 -> 150 | R31: 150 | S31: =SUM(G31:R31) -> 1800 | T31: röda korset
A32: In | B32: el | C32: =0*355.9+200 -> 200 | E32: =S118 -> 373 | F32: =0+D32 -> 0 | G32: =0*355.9+200 -> 200 | H32: =0*355.9+200 -> 200 | I32: =0*355.9+200 -> 200 | J32: =0*355.9+200 -> 200 | K32: =0*355.9+200 -> 200 | L32: =0*355.9+200 -> 200 | M32: =0*355.9+200 -> 200 | N32: 200 | O32: =0*355.9+200 -> 200 | P32: 200 | Q32: =0*355.9+200 -> 200 | R32: 200 | S32: =SUM(G32:R32) -> 2400 | T32: el
A33: In | B33: internet | C33: =188*0+299 -> 299 | E33: =S119 -> 0 | F33: =0+D33 -> 0 | G33: =188*0+299 -> 299 | H33: =188*0+299 -> 299 | I33: =188*0+299 -> 299 | J33: =188*0+299 -> 299 | K33: =188*0+299 -> 299 | L33: =188*0+299 -> 299 | M33: =188*0+299 -> 299 | N33: 299 | O33: =188*0+299 -> 299 | P33: 299 | Q33: =188*0+299 -> 299 | R33: 299 | S33: =SUM(G33:R33) -> 3588 | T33: internet
A34: In | B34: telefonsamtal | C34: =(39+69+120)*0+(299+15+40)*0+339*0+(354-339)*0+220+299-50+50 -> 519 | E34: =S120 -> 255 | F34: =0+D34 -> 0 | G34: =(39+69+120)*0+(299+15+40)*0+339*0+(354-339)*0+220+299-50 -> 469 | H34: =(39+69+120)*0+(299+15+40)*0+339*0+(354-339)*0+220+299-50 -> 469 | I34: =(39+69+120)*0+(299+15+40)*0+339*0+(354-339)*0+220+299-50+50 -> 519 | J34: =(39+69+120)*0+(299+15+40)*0+339*0+(354-339)*0+220+299-50+50 -> 519 | K34: =(39+69+120)*0+(299+15+40)*0+339*0+(354-339)*0+220+299-50+50 -> 519 | L34: =(39+69+120)*0+(299+15+40)*0+339*0+(354-339)*0+220+299-50+50 -> 519 | M34: =(39+69+120)*0+(299+15+40)*0+339*0+(354-339)*0+220+299-50+50 -> 519 | N34: 519 | O34: =(39+69+120)*0+(299+15+40)*0+339*0+(354-339)*0+220+299-50+50 -> 519 | P34: 519 | Q34: =(39+69+120)*0+(299+15+40)*0+339*0+(354-339)*0+220+299-50+50 -> 519 | R34: 519 | S34: =SUM(G34:R34) -> 6128 | T34: telefonsamtal | W34: =R34-40 -> 479
A35: In | B35: hygien (disk, tvätt o tvål etc) | C35: =20+10 -> 30 | E35: =S121 -> 360 | F35: =0+D35 -> 0 | G35: =20+10 -> 30 | H35: =20+10 -> 30 | I35: =20+10 -> 30 | J35: =20+10 -> 30 | K35: =20+10 -> 30 | L35: =20+10 -> 30 | M35: =20+10 -> 30 | N35: 30 | O35: =20+10 -> 30 | P35: 30 | Q35: =20+10 -> 30 | R35: 30 | S35: =SUM(G35:R35) -> 360 | T35: hygien (disk, tvätt o tvål etc)
A36: In | B36: hemlagad mat | C36: =850+50-300 -> 600 | E36: =S122 -> 3492.93 | F36: =0+D36 -> 0 | G36: =850+50 -> 900 | H36: =850+50 -> 900 | I36: =850+50-300 -> 600 | J36: =850+50-300 -> 600 | K36: =850+50-300 -> 600 | L36: =850+50-300 -> 600 | M36: =850+50-300 -> 600 | N36: 600 | O36: =850+50-300 -> 600 | P36: 600 | Q36: =850+50-300 -> 600 | R36: 600 | S36: =SUM(G36:R36) -> 7800 | T36: hemlagad mat
A37: In | B37: hemlagad lunch | C37: =(226/12)*(15+20)*0.5*0+50*0 -> 0 | E37: =S123 -> 0 | F37: =0+D37 -> 0 | G37: =(226/12)*(15+20)*0.5*0+50*0 -> 0 | H37: =(226/12)*(15+20)*0.5*0+50*0 -> 0 | I37: =(226/12)*(15+20)*0.5*0+50*0 -> 0 | J37: =(226/12)*(15+20)*0.5*0+50*0 -> 0 | K37: =(226/12)*(15+20)*0.5*0+50*0 -> 0 | L37: =(226/12)*(15+20)*0.5*0+50*0 -> 0 | M37: =(226/12)*(15+20)*0.5*0+50*0 -> 0 | N37: 0 | O37: =(226/12)*(15+20)*0.5*0+50*0 -> 0 | P37: 0 | Q37: =(226/12)*(15+20)*0.5*0+50*0 -> 0 | R37: 0 | S37: =SUM(G37:R37) -> 0 | T37: hemlagad lunch
A38: In | B38: lunch utemat | C38: =((780/11)*227)/12+10*10 -> 1441.3636 | E38: =S124 -> 2622.3636 | F38: =0+D38 -> 0 | G38: =((780/11)*227)/12+10*10 -> 1441.3636 | H38: =((780/11)*227)/12+10*10 -> 1441.3636 | I38: =((780/11)*227)/12+10*10 -> 1441.3636 | J38: =((780/11)*227)/12+10*10 -> 1441.3636 | K38: =((780/11)*227)/12+10*10 -> 1441.3636 | L38: =((780/11)*227)/12+10*10 -> 1441.3636 | M38: =((780/11)*227)/12+10*10 -> 1441.3636 | N38: 1441.3636 | O38: =((780/11)*227)/12+10*10 -> 1441.3636 | P38: 1441.3636 | Q38: =((780/11)*227)/12+10*10 -> 1441.3636 | R38: 1441.3636 | S38: =SUM(G38:R38) -> 17296.364 | T38: lunch utemat | V38: russel tot | W38: =R38-45 -> 1396.3636
A39: In | B39: nöjes utemat | C39: =(300*2+250*2)*0+(900+500)*1+0*(45*5*4.5+450)+800-100 -> 2100 | E39: =S125 -> 7804.36 | F39: =0+D39 -> 0 | G39: =(300*2+250*2)*0+(900+500)*1+0*(45*5*4.5+450)+6000 -> 7400 | H39: =(300*2+250*2)*0+(900+500)*1+0*(45*5*4.5+450) -> 1400 | I39: =(300*2+250*2)*0+(900+500)*1+0*(45*5*4.5+450)+800 -> 2200 | J39: =(300*2+250*2)*0+(900+500)*1+0*(45*5*4.5+450)+800+2500 -> 4700 | K39: =(300*2+250*2)*0+(900+500)*1+0*(45*5*4.5+450)+800+2500 -> 4700 | L39: =(300*2+250*2)*0+(900+500)*1+0*(45*5*4.5+450)+800-100 -> 2100 | M39: =(300*2+250*2)*0+(900+500)*1+0*(45*5*4.5+450)+800-100 -> 2100 | N39: 2100 | O39: =(300*2+250*2)*0+(900+500)*1+0*(45*5*4.5+450)+800-100 -> 2100 | P39: =2100 -> 2100 | Q39: =(300*2+250*2)*0+(900+500)*1+0*(45*5*4.5+450)+800-100 -> 2100 | R39: 2100 | S39: =SUM(G39:R39) -> 35100 | T39: nöjes utemat | V39: =C39+C40+C41+C42+C43+C52+C55+C56 -> 4274.9997
A40: In | B40: mat i samband med supa | C40: =2*250*0+1477.49969696969 -> 1477.4997 | E40: =S126 -> 7266.1964 | F40: =0+D40 -> 0 | G40: =2*250*0+1477.49969696969 -> 1477.4997 | H40: =2*250*0+1477.49969696969 -> 1477.4997 | I40: =2*250*0+1477.49969696969 -> 1477.4997 | J40: =2*250*0+1477.49969696969 -> 1477.4997 | K40: =2*250*0+1477.49969696969 -> 1477.4997 | L40: =2*250*0+1477.49969696969 -> 1477.4997 | M40: =2*250*0+1477.49969696969 -> 1477.4997 | N40: 1477.4997 | O40: =2*250*0+1477.49969696969 -> 1477.4997 | P40: 1477.4997 | Q40: =2*250*0+1477.49969696969 -> 1477.4997 | R40: 1477.4997 | S40: =SUM(G40:R40) -> 17729.996 | T40: mat i samband med supa | W40: =R40-50 -> 1427.4997 | X40: =17-14 -> 3
A41: In | B41: alkohol | C41: =500*2-1000+4.5*55 -> 247.5 | E41: =S127 -> -1699 | F41: =0+D41 -> 0 | G41: =500*2-1000+4.5*55 -> 247.5 | H41: =500*2-1000+4.5*55 -> 247.5 | I41: =500*2-1000+4.5*55 -> 247.5 | J41: =500*2-1000+4.5*55 -> 247.5 | K41: =500*2-1000+4.5*55 -> 247.5 | L41: =500*2-1000+4.5*55 -> 247.5 | M41: =500*2-1000+4.5*55 -> 247.5 | N41: 247.5 | O41: =500*2-1000+4.5*55 -> 247.5 | P41: 247.5 | Q41: =500*2-1000+4.5*55 -> 247.5 | R41: 247.5 | S41: =SUM(G41:R41) -> 2970 | T41: alkohol | W41: =R41-50 -> 197.5
...

Sheet Villkor 1 år (2014)
A1: y | B1: m | D1: d | E1: n | F1: e | G1: t | J1: b | L1: år | M1: =2014 -> 2014 | N1: Steg mellan varje | O1: =21-1 -> 20
A2: =$M$1 -> 2014 | B2: 1 | J2: hyra (inkl. 1k amortering)
A3: y | B3: m | D3: d | E3: n | F3: e | G3: t | J3: b
A4: =$M$1 -> 2014 | B4: 1 | J4: si och akassa
A5: y | B5: m | D5: d | E5: n | F5: e | G5: t | J5: b
A6: =$M$1 -> 2014 | B6: 1 | J6: hemförsäkring
A7: y | B7: m | D7: d | E7: n | F7: e | G7: t | J7: b
A8: =$M$1 -> 2014 | B8: 1 | J8: liv- o sjukförsäkring etc
A9: y | B9: m | D9: d | E9: n | F9: e | G9: t | J9: b
A10: =$M$1 -> 2014 | B10: 1 | J10: stockholms stads bostadskö
A11: y | B11: m | D11: d | E11: n | F11: e | G11: t | J11: b
A12: =$M$1 -> 2014 | B12: 1 | J12: csn
A13: y | B13: m | D13: d | E13: n | F13: e | G13: t | J13: b
A14: =$M$1 -> 2014 | B14: 1 | J14: röda korset
A15: y | B15: m | D15: d | E15: n | F15: e | G15: t | J15: b
A16: =$M$1 -> 2014 | B16: 1 | J16: el
A17: y | B17: m | D17: d | E17: n | F17: e | G17: t | J17: b
A18: =$M$1 -> 2014 | B18: 1 | J18: internet
A19: y | B19: m | D19: d | E19: n | F19: e | G19: t | J19: b
A20: =$M$1 -> 2014 | B20: 1 | J20: telefonsamtal
A21: y | B21: m | D21: d | E21: n | F21: e | G21: t | J21: b
A22: =$M$1 -> 2014 | B22: 1 | J22: hygien (disk, tvätt o tvål etc)
A23: y | B23: m | D23: d | E23: n | F23: e | G23: t | J23: b
A24: =$M$1 -> 2014 | B24: 1 | J24: hemlagad mat
A25: y | B25: m | D25: d | E25: n | F25: e | G25: t | J25: b
A26: =$M$1 -> 2014 | B26: 1 | J26: hemlagad lunch
A27: y | B27: m | D27: d | E27: n | F27: e | G27: t | J27: b
A28: =$M$1 -> 2014 | B28: 1 | J28: lunch utemat
A29: y | B29: m | D29: d | E29: n | F29: e | G29: t | J29: b
A30: =$M$1 -> 2014 | B30: 1 | J30: nöjes utemat
A31: y | B31: m | D31: d | E31: n | F31: e | G31: t | J31: b
A32: =$M$1 -> 2014 | B32: 1 | J32: mat i samband med supa
A33: y | B33: m | D33: d | E33: n | F33: e | G33: t | J33: b
A34: =$M$1 -> 2014 | B34: 1 | J34: alkohol
A35: y | B35: m | D35: d | E35: n | F35: e | G35: t | J35: b
A36: =$M$1 -> 2014 | B36: 1 | J36: taxi efter supa
A37: y | B37: m | D37: d | E37: n | F37: e | G37: t | J37: b
A38: =$M$1 -> 2014 | B38: 1 | J38: Buss etc i samband med supa
A39: y | B39: m | D39: d | E39: n | F39: e | G39: t | J39: b
A40: =$M$1 -> 2014 | B40: 1 | J40: oväntade utgifter
...
